Workbook

Sheet README
B2: Sentosa CMS — FRD v0.5 vs. Current Build: Handover Checklist
B3: Prepared for BA handover — comparing 'SDC IIS CMS FRD v0.5_SDC.pdf' against the current sts-bnk (Sentosa) source code.
B5: Purpose
B6: This workbook lists every feature/requirement in FRD v0.5 (85 pages, sections 1-16), grouped by CMS module, with a build-status verdict checked directly against the current source code (not against older internal planning docs, which may be out of date).
B8: How to use it
B9: - 'Feature Checklist' tab: one row per requirement. Use the Status dropdown (column F) to re-classify as you verify; conditional colour updates automatically. Tick column G once you've personally re-confirmed a row.
B10: - 'Open Items - Need Shinfeng' tab: everything that cannot be marked Built/Not-Built until the BA (Wong Shin Feng) confirms intent — includes the FRD's own Section 15 'Open Items', blank tables in the FRD itself (3.3.4, Section 14), and material code/FRD contradictions found during this review.
B11: - 'Summary' tab: auto-counted totals per module and overall, driven by formulas off the Feature Checklist tab.
B13: Status legend
B14: Built — implemented and verified in current code.
B15: Partially Built — some part implemented; gap described in the Notes column.
B16: Not Built — no implementation found after a repo-wide search.
... B25: Prepared: 2026-07-16

Sheet Summary
A1: Sentosa CMS — Build Status Summary by Module
A3: Module | B3: Built | C3: Partially Built | D3: Not Built | E3: N/A (by design) | F3: Unclear / Needs BA | G3: Total
A4: 1. CMS Overview & Dashboard | B4: =COUNTIFS('Feature Checklist'!$B:$B,$A4,'Feature Checklist'!$F:$F,"Built")+COUNTIFS('Feature Checklist'!$B:$B,$A4,'Feature Checklist'!$F:$F,"Built (config only, not consumed)")+COUNTIFS('Feature Checklist'!$B:$B,$A4,'Feature Checklist'!$F:$F,"Built (manual)")+COUNTIFS('Feature Checklist'!$B:$B,$A4,'Feature Checklist'!$F:$F,"Built (informational)") -> 5 | C4: =COUNTIFS('Feature Checklist'!$B:$B,$A4,'Feature Checklist'!$F:$F,"Partially Built") -> 4 | D4: =COUNTIFS('Feature Checklist'!$B:$B,$A4,'Feature Checklist'!$F:$F,"Not Built") -> 9 | E4: =COUNTIFS('Feature Checklist'!$B:$B,$A4,'Feature Checklist'!$F:$F,"N/A (excluded by design)") -> 0 | F4: =COUNTIFS('Feature Checklist'!$B:$B,$A4,'Feature Checklist'!$F:$F,"Unclear / Needs BA Confirmation") -> 0 | G4: =SUM(B4:F4) -> 18
A5: 2. UCS Integration | B5: =COUNTIFS('Feature Checklist'!$B:$B,$A5,'Feature Checklist'!$F:$F,"Built")+COUNTIFS('Feature Checklist'!$B:$B,$A5,'Feature Checklist'!$F:$F,"Built (config only, not consumed)")+COUNTIFS('Feature Checklist'!$B:$B,$A5,'Feature Checklist'!$F:$F,"Built (manual)")+COUNTIFS('Feature Checklist'!$B:$B,$A5,'Feature Checklist'!$F:$F,"Built (informational)") -> 0 | C5: =COUNTIFS('Feature Checklist'!$B:$B,$A5,'Feature Checklist'!$F:$F,"Partially Built") -> 1 | D5: =COUNTIFS('Feature Checklist'!$B:$B,$A5,'Feature Checklist'!$F:$F,"Not Built") -> 7 | E5: =COUNTIFS('Feature Checklist'!$B:$B,$A5,'Feature Checklist'!$F:$F,"N/A (excluded by design)") -> 0 | F5: =COUNTIFS('Feature Checklist'!$B:$B,$A5,'Feature Checklist'!$F:$F,"Unclear / Needs BA Confirmation") -> 0 | G5: =SUM(B5:F5) -> 8
A6: 3. User Roles & Permissions | B6: =COUNTIFS('Feature Checklist'!$B:$B,$A6,'Feature Checklist'!$F:$F,"Built")+COUNTIFS('Feature Checklist'!$B:$B,$A6,'Feature Checklist'!$F:$F,"Built (config only, not consumed)")+COUNTIFS('Feature Checklist'!$B:$B,$A6,'Feature Checklist'!$F:$F,"Built (manual)")+COUNTIFS('Feature Checklist'!$B:$B,$A6,'Feature Checklist'!$F:$F,"Built (informational)") -> 6 | C6: =COUNTIFS('Feature Checklist'!$B:$B,$A6,'Feature Checklist'!$F:$F,"Partially Built") -> 4 | D6: =COUNTIFS('Feature Checklist'!$B:$B,$A6,'Feature Checklist'!$F:$F,"Not Built") -> 6 | E6: =COUNTIFS('Feature Checklist'!$B:$B,$A6,'Feature Checklist'!$F:$F,"N/A (excluded by design)") -> 0 | F6: =COUNTIFS('Feature Checklist'!$B:$B,$A6,'Feature Checklist'!$F:$F,"Unclear / Needs BA Confirmation") -> 2 | G6: =SUM(B6:F6) -> 18
A7: 4. Case Data Model | B7: =COUNTIFS('Feature Checklist'!$B:$B,$A7,'Feature Checklist'!$F:$F,"Built")+COUNTIFS('Feature Checklist'!$B:$B,$A7,'Feature Checklist'!$F:$F,"Built (config only, not consumed)")+COUNTIFS('Feature Checklist'!$B:$B,$A7,'Feature Checklist'!$F:$F,"Built (manual)")+COUNTIFS('Feature Checklist'!$B:$B,$A7,'Feature Checklist'!$F:$F,"Built (informational)") -> 7 | C7: =COUNTIFS('Feature Checklist'!$B:$B,$A7,'Feature Checklist'!$F:$F,"Partially Built") -> 0 | D7: =COUNTIFS('Feature Checklist'!$B:$B,$A7,'Feature Checklist'!$F:$F,"Not Built") -> 0 | E7: =COUNTIFS('Feature Checklist'!$B:$B,$A7,'Feature Checklist'!$F:$F,"N/A (excluded by design)") -> 0 | F7: =COUNTIFS('Feature Checklist'!$B:$B,$A7,'Feature Checklist'!$F:$F,"Unclear / Needs BA Confirmation") -> 2 | G7: =SUM(B7:F7) -> 9
A8: 5. Incident Management | B8: =COUNTIFS('Feature Checklist'!$B:$B,$A8,'Feature Checklist'!$F:$F,"Built")+COUNTIFS('Feature Checklist'!$B:$B,$A8,'Feature Checklist'!$F:$F,"Built (config only, not consumed)")+COUNTIFS('Feature Checklist'!$B:$B,$A8,'Feature Checklist'!$F:$F,"Built (manual)")+COUNTIFS('Feature Checklist'!$B:$B,$A8,'Feature Checklist'!$F:$F,"Built (informational)") -> 29 | C8: =COUNTIFS('Feature Checklist'!$B:$B,$A8,'Feature Checklist'!$F:$F,"Partially Built") -> 6 | D8: =COUNTIFS('Feature Checklist'!$B:$B,$A8,'Feature Checklist'!$F:$F,"Not Built") -> 6 | E8: =COUNTIFS('Feature Checklist'!$B:$B,$A8,'Feature Checklist'!$F:$F,"N/A (excluded by design)") -> 0 | F8: =COUNTIFS('Feature Checklist'!$B:$B,$A8,'Feature Checklist'!$F:$F,"Unclear / Needs BA Confirmation") -> 0 | G8: =SUM(B8:F8) -> 41
A9: 6. Fault Reporting | B9: =COUNTIFS('Feature Checklist'!$B:$B,$A9,'Feature Checklist'!$F:$F,"Built")+COUNTIFS('Feature Checklist'!$B:$B,$A9,'Feature Checklist'!$F:$F,"Built (config only, not consumed)")+COUNTIFS('Feature Checklist'!$B:$B,$A9,'Feature Checklist'!$F:$F,"Built (manual)")+COUNTIFS('Feature Checklist'!$B:$B,$A9,'Feature Checklist'!$F:$F,"Built (informational)") -> 5 | C9: =COUNTIFS('Feature Checklist'!$B:$B,$A9,'Feature Checklist'!$F:$F,"Partially Built") -> 2 | D9: =COUNTIFS('Feature Checklist'!$B:$B,$A9,'Feature Checklist'!$F:$F,"Not Built") -> 0 | E9: =COUNTIFS('Feature Checklist'!$B:$B,$A9,'Feature Checklist'!$F:$F,"N/A (excluded by design)") -> 1 | F9: =COUNTIFS('Feature Checklist'!$B:$B,$A9,'Feature Checklist'!$F:$F,"Unclear / Needs BA Confirmation") -> 0 | G9: =SUM(B9:F9) -> 8
A10: 7. Task Management | B10: =COUNTIFS('Feature Checklist'!$B:$B,$A10,'Feature Checklist'!$F:$F,"Built")+COUNTIFS('Feature Checklist'!$B:$B,$A10,'Feature Checklist'!$F:$F,"Built (config only, not consumed)")+COUNTIFS('Feature Checklist'!$B:$B,$A10,'Feature Checklist'!$F:$F,"Built (manual)")+COUNTIFS('Feature Checklist'!$B:$B,$A10,'Feature Checklist'!$F:$F,"Built (informational)") -> 5 | C10: =COUNTIFS('Feature Checklist'!$B:$B,$A10,'Feature Checklist'!$F:$F,"Partially Built") -> 1 | D10: =COUNTIFS('Feature Checklist'!$B:$B,$A10,'Feature Checklist'!$F:$F,"Not Built") -> 0 | E10: =COUNTIFS('Feature Checklist'!$B:$B,$A10,'Feature Checklist'!$F:$F,"N/A (excluded by design)") -> 0 | F10: =COUNTIFS('Feature Checklist'!$B:$B,$A10,'Feature Checklist'!$F:$F,"Unclear / Needs BA Confirmation") -> 0 | G10: =SUM(B10:F10) -> 6
A11: 8. Events Master List | B11: =COUNTIFS('Feature Checklist'!$B:$B,$A11,'Feature Checklist'!$F:$F,"Built")+COUNTIFS('Feature Checklist'!$B:$B,$A11,'Feature Checklist'!$F:$F,"Built (config only, not consumed)")+COUNTIFS('Feature Checklist'!$B:$B,$A11,'Feature Checklist'!$F:$F,"Built (manual)")+COUNTIFS('Feature Checklist'!$B:$B,$A11,'Feature Checklist'!$F:$F,"Built (informational)") -> 12 | C11: =COUNTIFS('Feature Checklist'!$B:$B,$A11,'Feature Checklist'!$F:$F,"Partially Built") -> 1 | D11: =COUNTIFS('Feature Checklist'!$B:$B,$A11,'Feature Checklist'!$F:$F,"Not Built") -> 0 | E11: =COUNTIFS('Feature Checklist'!$B:$B,$A11,'Feature Checklist'!$F:$F,"N/A (excluded by design)") -> 0 | F11: =COUNTIFS('Feature Checklist'!$B:$B,$A11,'Feature Checklist'!$F:$F,"Unclear / Needs BA Confirmation") -> 1 | G11: =SUM(B11:F11) -> 14
A12: 9. e-Diary | B12: =COUNTIFS('Feature Checklist'!$B:$B,$A12,'Feature Checklist'!$F:$F,"Built")+COUNTIFS('Feature Checklist'!$B:$B,$A12,'Feature Checklist'!$F:$F,"Built (config only, not consumed)")+COUNTIFS('Feature Checklist'!$B:$B,$A12,'Feature Checklist'!$F:$F,"Built (manual)")+COUNTIFS('Feature Checklist'!$B:$B,$A12,'Feature Checklist'!$F:$F,"Built (informational)") -> 2 | C12: =COUNTIFS('Feature Checklist'!$B:$B,$A12,'Feature Checklist'!$F:$F,"Partially Built") -> 5 | D12: =COUNTIFS('Feature Checklist'!$B:$B,$A12,'Feature Checklist'!$F:$F,"Not Built") -> 3 | E12: =COUNTIFS('Feature Checklist'!$B:$B,$A12,'Feature Checklist'!$F:$F,"N/A (excluded by design)") -> 0 | F12: =COUNTIFS('Feature Checklist'!$B:$B,$A12,'Feature Checklist'!$F:$F,"Unclear / Needs BA Confirmation") -> 0 | G12: =SUM(B12:F12) -> 10
A13: 10. Broadcast & Notification | B13: =COUNTIFS('Feature Checklist'!$B:$B,$A13,'Feature Checklist'!$F:$F,"Built")+COUNTIFS('Feature Checklist'!$B:$B,$A13,'Feature Checklist'!$F:$F,"Built (config only, not consumed)")+COUNTIFS('Feature Checklist'!$B:$B,$A13,'Feature Checklist'!$F:$F,"Built (manual)")+COUNTIFS('Feature Checklist'!$B:$B,$A13,'Feature Checklist'!$F:$F,"Built (informational)") -> 5 | C13: =COUNTIFS('Feature Checklist'!$B:$B,$A13,'Feature Checklist'!$F:$F,"Partially Built") -> 5 | D13: =COUNTIFS('Feature Checklist'!$B:$B,$A13,'Feature Checklist'!$F:$F,"Not Built") -> 14 | E13: =COUNTIFS('Feature Checklist'!$B:$B,$A13,'Feature Checklist'!$F:$F,"N/A (excluded by design)") -> 0 | F13: =COUNTIFS('Feature Checklist'!$B:$B,$A13,'Feature Checklist'!$F:$F,"Unclear / Needs BA Confirmation") -> 3 | G13: =SUM(B13:F13) -> 27
A14: 11. Crisis Management & Emergency Recall | B14: =COUNTIFS('Feature Checklist'!$B:$B,$A14,'Feature Checklist'!$F:$F,"Built")+COUNTIFS('Feature Checklist'!$B:$B,$A14,'Feature Checklist'!$F:$F,"Built (config only, not consumed)")+COUNTIFS('Feature Checklist'!$B:$B,$A14,'Feature Checklist'!$F:$F,"Built (manual)")+COUNTIFS('Feature Checklist'!$B:$B,$A14,'Feature Checklist'!$F:$F,"Built (informational)") -> 2 | C14: =COUNTIFS('Feature Checklist'!$B:$B,$A14,'Feature Checklist'!$F:$F,"Partially Built") -> 0 | D14: =COUNTIFS('Feature Checklist'!$B:$B,$A14,'Feature Checklist'!$F:$F,"Not Built") -> 9 | E14: =COUNTIFS('Feature Checklist'!$B:$B,$A14,'Feature Checklist'!$F:$F,"N/A (excluded by design)") -> 0 | F14: =COUNTIFS('Feature Checklist'!$B:$B,$A14,'Feature Checklist'!$F:$F,"Unclear / Needs BA Confirmation") -> 0 | G14: =SUM(B14:F14) -> 11
A15: 12. Reporting & Data Export | B15: =COUNTIFS('Feature Checklist'!$B:$B,$A15,'Feature Checklist'!$F:$F,"Built")+COUNTIFS('Feature Checklist'!$B:$B,$A15,'Feature Checklist'!$F:$F,"Built (config only, not consumed)")+COUNTIFS('Feature Checklist'!$B:$B,$A15,'Feature Checklist'!$F:$F,"Built (manual)")+COUNTIFS('Feature Checklist'!$B:$B,$A15,'Feature Checklist'!$F:$F,"Built (informational)") -> 0 | C15: =COUNTIFS('Feature Checklist'!$B:$B,$A15,'Feature Checklist'!$F:$F,"Partially Built") -> 0 | D15: =COUNTIFS('Feature Checklist'!$B:$B,$A15,'Feature Checklist'!$F:$F,"Not Built") -> 8 | E15: =COUNTIFS('Feature Checklist'!$B:$B,$A15,'Feature Checklist'!$F:$F,"N/A (excluded by design)") -> 0 | F15: =COUNTIFS('Feature Checklist'!$B:$B,$A15,'Feature Checklist'!$F:$F,"Unclear / Needs BA Confirmation") -> 0 | G15: =SUM(B15:F15) -> 8
... A17: 14. Non-Functional Requirements | B17: =COUNTIFS('Feature Checklist'!$B:$B,$A17,'Feature Checklist'!$F:$F,"Built")+COUNTIFS('Feature Checklist'!$B:$B,$A17,'Feature Checklist'!$F:$F,"Built (config only, not consumed)")+COUNTIFS('Feature Checklist'!$B:$B,$A17,'Feature Checklist'!$F:$F,"Built (manual)")+COUNTIFS('Feature Checklist'!$B:$B,$A17,'Feature Checklist'!$F:$F,"Built (informational)") -> 1 | C17: =COUNTIFS('Feature Checklist'!$B:$B,$A17,'Feature Checklist'!$F:$F,"Partially Built") -> 0 | D17: =COUNTIFS('Feature Checklist'!$B:$B,$A17,'Feature Checklist'!$F:$F,"Not Built") -> 1 | E17: =COUNTIFS('Feature Checklist'!$B:$B,$A17,'Feature Checklist'!$F:$F,"N/A (excluded by design)") -> 0 | F17: =COUNTIFS('Feature Checklist'!$B:$B,$A17,'Feature Checklist'!$F:$F,"Unclear / Needs BA Confirmation") -> 5 | G17: =SUM(B17:F17) -> 7
A18: TOTAL — All Modules | B18: =SUM(B4:B17) -> 90 | C18: =SUM(C4:C17) -> 37 | D18: =SUM(D4:D17) -> 75 | E18: =SUM(E4:E17) -> 1 | F18: =SUM(F4:F17) -> 14 | G18: =SUM(G4:G17) -> 217
A21: Open items requiring Shinfeng (BA) confirmation: | B21: =19 -> 19
A22: See 'Open Items - Need Shinfeng' tab for full detail.

Sheet Feature Checklist
A1: # | B1: Module | C1: Sub-Area / FRD Ref | D1: Feature / Requirement | E1: FRD Section | F1: Status | G1: Confirmed? | H1: Evidence (Current Code) | I1: Notes / Gap Description
A2: 1 | B2: 1. CMS Overview & Dashboard | C2: 2.1-2.2 Modules | D2: CMS covers Incident/Fault/Task/NOP/Events/e-Diary/Distribution Group/Broadcast/Dashboard/Sys Config | E2: 2.1-2.2 | F2: Built | G2: No | H2: Matching route folders exist for all modules | I2: Central Rostering is explicitly 'proposed' in FRD (15.4) — correctly not built
A3: 2 | B3: 1. CMS Overview & Dashboard | C3: 2.2 Modules | D3: Crisis Recall as standalone module | E3: 2.2 | F3: Not Built | G3: No | H3: grep 'Crisis Recall' -> only a label in admin/roles matrix, no page/API/data model
A4: 3 | B4: 1. CMS Overview & Dashboard | C4: 2.3.1 Auth | D4: WOG SSO authentication for SDC users | E4: 2.3.1 | F4: Not Built | G4: No | H4: RoleContext.tsx is a client-side role switcher via localStorage, no SSO/login flow | I4: No real auth exists at all
A5: 4 | B5: 1. CMS Overview & Dashboard | C5: 2.3.1 Auth | D5: Non-SSO username/password + 2FA | E5: 2.3.1 | F5: Not Built | G5: No | H5: No login form or password field anywhere in src/app
A6: 5 | B6: 1. CMS Overview & Dashboard | C6: 2.3.1 Auth | D6: Deny access / redirect if no active CMS account or role | E6: 2.3.1 | F6: Not Built | G6: No | H6: No such gate; app loads straight into Dashboard
A7: 6 | B7: 1. CMS Overview & Dashboard | C7: 2.4.1 Navigation | D7: Nav items: Dashboard, Case Mgmt, Incident, Fault, Task, Events, NOP, Broadcast, Statistics, Sys Config | E7: 2.4.1 | F7: Built | G7: No | H7: Sidebar.tsx NAV_GROUPS/ADMIN_ITEMS map 1:1 to real routes | I7: Incident/Fault/Task are sub-tabs inside /case-management rather than top-level nav - functionally equivalent
A8: 7 | B8: 1. CMS Overview & Dashboard | C8: 2.4.1 Navigation | D8: Nav items filtered by assigned role | E8: 2.4.1 | F8: Partially Built | G8: No | H8: Sidebar.tsx only gates the Administration section (role==='System Administrator'); Ops/Planning/Comms/Analytics items render for every role | I8: Responder/Stakeholder should have narrower nav per FRD 3.1 role table
A9: 8 | B9: 1. CMS Overview & Dashboard | C9: 2.4.2 Summary Metrics | D9: 9 dashboard counters: Active Cases, Incidents Reported, Unclosed Incidents, Faults Reported, Unclosed Faults, Active Tasks, Overdue Tasks, Events Today, Active NOPs | E9: 2.4.2 | F9: Built | G9: No | H9: src/app/page.tsx lines ~98-104, 60-64 | I9: All 9 counters exist and compute correctly
A10: 9 | B10: 1. CMS Overview & Dashboard | C10: 2.4.2 Summary Metrics | D10: Each metric filterable by date/time range | E10: 2.4.2 | F10: Partially Built | G10: No | H10: page.tsx lines 160-164 UI text itself says 'Affects: Incidents Reported, Faults Reported' only | I10: Only 2 of 9 metrics respond to the date filter; FRD says 'each'
A11: 10 | B11: 1. CMS Overview & Dashboard | C11: 2.4.3-2.4.4 Map | D11: Events Today metric + events surfaced on dashboard | E11: 2.4.3 | F11: Built | G11: No | H11: page.tsx lines 263-273
A12: 11 | B12: 1. CMS Overview & Dashboard | C12: 2.4.4 Map | D12: Events shown as boundary/area overlays on 2D map | E12: 2.4.4 | F12: Partially Built | G12: No | H12: MapComponent.tsx updateEventMarkers plots point pins only; BoundaryMapDrawer polygon data (EventRecord.boundaryCoordinates) is captured but never rendered on the dashboard map
A13: 12 | B13: 1. CMS Overview & Dashboard | C13: 2.4.4 Map | D13: 2D map of Sentosa using OneMap API | E13: 2.4.4 | F13: Not Built | G13: No | H13: MapComponent.tsx uses CartoDB/OpenStreetMap tiles; only a cosmetic label 'OneMap API Layout' exists in incidents/new/page.tsx | I13: No real OneMap integration/geocoding anywhere in repo
A14: 13 | B14: 1. CMS Overview & Dashboard | C14: 2.4.4 Map | D14: Incident pins geocoded from text address via OneMap | E14: 2.4.4 | F14: Partially Built | G14: No | H14: MapComponent.tsx plots directly from stored lat/lng; no geocoding API call exists | I14: Manual pin-drop path works; auto-geocode path does not
A15: 14 | B15: 1. CMS Overview & Dashboard | C15: 2.4.4 Map | D15: Faults shown as separate drop-pin map layer | E15: 2.4.4 | F15: Not Built | G15: No | H15: MapComponent has no 'faults' prop at all; dashboard fetches faults but never passes them to the map
A16: 15 | B16: 1. CMS Overview & Dashboard | C16: 2.4.4 Map | D16: Active Works (NOP) boundary overlay layer | E16: 2.4.4 | F16: Not Built | G16: No | H16: No NOP-related code in MapComponent; BoundaryMapDrawer.tsx comment itself says NOP map integration is an unbuilt follow-on
A17: 16 | B17: 1. CMS Overview & Dashboard | C17: 2.4.4 Map | D17: Pin clustering at zoom levels | E17: 2.4.4 | F17: Not Built | G17: No | H17: No clustering library wired in (grep 'markercluster' -> no matches)
A18: 17 | B18: 1. CMS Overview & Dashboard | C18: 2.4.4 Map | D18: Pin click -> summary panel with link to full record | E18: 2.4.4 | F18: Built | G18: No | H18: MapComponent.tsx popupContent lines ~141-171
A19: 18 | B19: 1. CMS Overview & Dashboard | C19: 2.4.4 Map | D19: Map coverage beyond Sentosa (Mt Faber/HarbourFront/VivoCity) | E19: 2.4.4 | F19: Not Built | G19: No | H19: MapComponent.tsx hardcodes maxBounds to Sentosa Island only (1.23-1.27 lat / 103.79-103.86 lng)
A20: 19 | B20: 2. UCS Integration | C20: 2.5.1 | D20: Live metric feed to UCS Dashboard | E20: 2.5.1 | F20: Not Built | G20: No | H20: No /ucs route or feed export anywhere in src/app/api | I20: 'UCS' only exists as a dropdown value for Incident reporting source
A21: 20 | B21: 2. UCS Integration | C21: 2.5.2 | D21: Embedded CMS functions within UCS (inline CRUD widgets) | E21: 2.5.2 | F21: Not Built | G21: No | H21: No embeddable widget/iframe/API contract for UCS consumption
A22: 21 | B22: 2. UCS Integration | C22: 2.5.3 | D22: Navigation from UCS to CMS record pages | E22: 2.5.3 | F22: Not Built | G22: No | H22: No UCS-side code in this repo to navigate from | I22: Inherently a UCS-side feature; confirm UCS is tracked in a separate repo
A23: 22 | B23: 2. UCS Integration | C23: 2.5.4 | D23: Incident creation from UCS, pre-populated from VA alert | E23: 2.5.4 | F23: Partially Built | G23: No | H23: Incident form supports 'UCS'/'VA' reporting-source tags + duplicate-check API exists | I23: No actual UCS-side trigger/embed exists, only the CMS tagging field
A24: 23 | B24: 2. UCS Integration | C24: 2.5.5 | D24: External weather alert forwarding -> advisory broadcast | E24: 2.5.5 | F24: Not Built | G24: No | H24: grep 'weather' -> only an incident sub-type label and a placeholder example string
A25: 24 | B25: 2. UCS Integration | C25: 2.5.6 | D25: Last 10 Actions widget (CMS -> UCS) | E25: 2.5.6 | F25: Not Built | G25: No | H25: grep 'last 10 action' -> zero matches
A26: 25 | B26: 2. UCS Integration | C26: 2.5.7 | D26: Broadcast integration with UCS | E26: 2.5.7 | F26: Not Built | G26: No | H26: Broadcast core exists in CMS but no UCS-facing surface or 'has draft broadcast' indicator
A27: 26 | B27: 2. UCS Integration | C27: 2.5.8 | D27: Crisis Recall with UCS | E27: 2.5.8 | F27: Not Built | G27: No | H27: No Crisis Recall feature exists in CMS at all (see module 11)
A28: 27 | B28: 3. User Roles & Permissions | C28: 3.1 Roles | D28: 11 named system roles (Sys Admin, Current Ops Admin, DM, DO, Controller, Responder, Stakeholder, Broadcast Recipient, Zone/Contract Mgr Non-IFM, OR Analyst, NOP Applicant/Approver) | E28: 3.1 | F28: Partially Built | G28: No | H28: RoleContext.tsx UserRole type only defines 7 switchable roles; 3 more exist as free-text strings in mock data (not selectable) | I28: Zone/Contract Manager, NOP Applicant, NOP Approver roles are entirely missing from code
A29: 28 | B29: 3. User Roles & Permissions | C29: 3.1 Roles | D29: Per-role system access matrix (view/edit/provisioning scope) | E29: 3.1 | F29: Built | G29: No | H29: admin/roles/page.tsx DEFAULT_ROLES/DEFAULT_MATRIX reproduces the FRD matrix closely | I29: IMPORTANT: this matrix is display-only - no other page reads it; real gating is hardcoded booleans per-page, so editing this admin screen has no functional effect
A30: 29 | B30: 3. User Roles & Permissions | C30: 3.1 Roles | D30: Current Ops Administrator gets Taxonomy management access (but not user/role provisioning) | E30: 3.1 | F30: Not Built | G30: No | H30: AdminGuard.tsx blocks ALL /admin/* pages incl. Taxonomy to non-'System Administrator' roles | I30: Contradicts FRD row granting Current Ops Admin taxonomy management
A31: 30 | B31: 3. User Roles & Permissions | C31: 3.2 DM Elevation | D31: DO (and per v0.5, Controller) elevation to DM permissions | E31: 3.2 | F31: Partially Built | G31: No | H31: Sidebar.tsx has a purely local, non-persisted 'isDOElevated' toggle only for Duty Officer role | I31: Not tied to backend, lost on refresh, doesn't gate any actual permission; Controller elevation not implemented at all
A32: 31 | B32: 3. User Roles & Permissions | C32: 3.2 DM Elevation | D32: Only Sys Admin/Current Ops Admin may grant elevation; shift start/end + grace period + granting admin recorded | E32: 3.2 | F32: Not Built | G32: No | H32: grep 'elevat' -> only the Sidebar toggle + static descriptive text in admin/roles and admin/users pages | I32: No grant workflow, no data model for elevation records
A33: 32 | B33: 3. User Roles & Permissions | C33: 3.2 DM Elevation | D33: Auto-revert after configurable grace period | E33: 3.2 | F33: Not Built | G33: No | H33: No grace-period timer/config found in admin/system-settings
A34: 33 | B34: 3. User Roles & Permissions | C34: 3.2 DM Elevation | D34: Elevated user cannot close/endorse incident they created themselves | E34: 3.2 / 5.10.1h | F34: Not Built | G34: No | H34: incidents/[...id]/page.tsx allows endorsement action with no creator/submitter identity check | I34: Same root gap as FRD 5.10.1(h)/(i) separation-of-duties rule
A35: 34 | B35: 3. User Roles & Permissions | C35: 3.3.1 Incident Matrix | D35: Incident status lifecycle per role/status action matrix | E35: 3.3.1 | F35: Built | G35: No | H35: API knownActions + incident detail page action buttons implement full lifecycle gating by isCtrl/isMgr/isRanger | I35: 'Live (Pending Controller Review)' modeled as a per-Responder lifecycleStatus, not an Incident-level status - a data-shape nuance, not a functional gap
A36: 35 | B36: 3. User Roles & Permissions | C36: 3.3.1 Incident Matrix | D36: Duty Officer cannot self-submit for endorsement; can only endorse if elevated AND not the original submitter | E36: 3.3.1 | F36: Partially Built | G36: No | H36: isMgr treats Duty Officer identically to Duty Manager with no elevation-state or submitter-identity check | I36: Any Duty Officer can approve/return endorsement at any time - no elevation gating, no self-endorsement block
A37: 36 | B37: 3. User Roles & Permissions | C37: 3.3.1 Incident Matrix | D37: SDC Stakeholder: view-only, scoped to authorised/relevant incident records | E37: 3.3.1 / 3.5 | F37: Partially Built | G37: No | H37: No Stakeholder branch in incident page -> defaults to read-only (satisfies view-only) but not scoped by type/department | I37: Stakeholder can view ALL incidents, not just relevant ones
A38: 37 | B38: 3. User Roles & Permissions | C38: 3.3.1 Incident Matrix | D38: Closed incident stays viewable ~12 hours post-closure (Controller) | E38: 3.3.1 | F38: Unclear / Needs BA Confirmation | G38: No | H38: No 12-hour visibility window logic found; closed incidents remain visible indefinitely | I38: Also unclear in FRD itself whether this means hide-after-12h or something else - needs BA clarification
A39: 38 | B39: 3. User Roles & Permissions | C39: 3.3.2 Task Matrix | D39: Task status lifecycle + role actions (Controller/DM/DO broad rights, Assignee restricted, no access pre-assignment) | E39: 3.3.2 | F39: Built | G39: No | H39: tasks/[...id]/page.tsx + api/tasks/[...id]/route.ts role gating (isCtrl/isMgr/isRanger/isAssignee) | I39: Code adds 2 extra statuses (Pending Closure, Returned) beyond FRD's 6-status table - functional enhancement, flag for FRD doc update
A40: 39 | B40: 3. User Roles & Permissions | C40: 3.3.3 e-Diary Matrix | D40: Create/View limited to Sys Admin/Current Ops Admin/DM/DO/Controller only | E40: 3.3.3 | F40: Built | G40: No | H40: EDiaryTab.tsx ALLOWED_ROLES matches FRD list (plus Current Ops Admin)
...

Sheet Open Items - Need Shinfeng
A1: # | B1: Module | C1: Open Item | D1: FRD Ref | E1: Why It's Open | F1: Suggested Question for Shinfeng | G1: Resolved?
A2: FRD's own explicitly-flagged Open Items (Section 15)
A3: 1 | B3: UCS | C3: Full list of CMS widgets/items to be embedded on the UCS dashboard is still under discussion with SDC. | D3: 15.1 | E3: Explicitly marked open in FRD itself | F3: What is the final/confirmed list of CMS widgets to embed on the UCS Dashboard? | G3: No
A4: 2 | B4: Incident | C4: Finalised Incident Type and Sub-type taxonomy to be confirmed. | D4: 15.2 | E4: Explicitly marked open in FRD itself; Appendix 16.1 lists a taxonomy but FRD flags it as provisional | F4: Is the Appendix 16.1 Incident Type/Sub-type list final, or are further changes expected? | G4: No
A5: 3 | B5: Broadcast | C5: Broadcast template content per incident type and crisis level to be confirmed. | D5: 15.3 | E5: Explicitly marked open in FRD itself | F5: What is the final broadcast template content per incident type / crisis level combination? | G5: No
A6: 4 | B6: Broadcast | C6: Broadcast timing rules and criteria governing which active incidents are surfaced in the interim broadcast queue are to be determined. | D6: 15.3 | E6: Explicitly marked open in FRD itself | F6: What are the timing rules/criteria for the End-of-Day Interim Broadcast queue? | G6: No
A7: 5 | B7: Broadcast | C7: Broadcast Matrix referenced as an open item. | D7: 15.3 / 10.6 | E7: FRD body text itself says '[TBC - Full broadcast matrix]' | F7: Please provide the finalised Broadcast Matrix (type/crisis level -> recipient group/channel). | G7: No
A8: 6 | B8: Central Rostering Module | C8: Proposed module for managing duty rosters (IOH staff, Rangers, contractors, on-duty personnel); scope, ownership, data input method, user groups, source of truth, and CMS notification integration all remain to be confirmed. | D8: 15.4 | E8: Explicitly marked open/proposed in FRD itself | F8: Is Central Rostering in scope for this phase? If so, what is the ownership/data model/integration approach? | G8: No
A10: Additional items found during code review that also need Shinfeng's confirmation
A11: 7 | B11: Roles & Permissions | C11: FRD section 3.3.4 'Events Management' role/status action matrix heading exists but the table itself is blank in the source PDF (jumps straight from heading to section 3.4). | D11: 3.3.4 | E11: FRD authoring gap - no table to build against | F11: Please provide the full Events Management role/status action matrix (who can create/edit/approve/delete Events by role and status). | G11: No
A12: 8 | B12: Non-Functional Requirements | C12: Entire Section 14 (Availability, Performance, Concurrent Users, Security, Session Management, Audit/Compliance, Data Retention) contains only headings with zero body content. | D12: 14.1-14.7 | E12: FRD authoring gap - no NFR requirements documented anywhere | F12: Please author the actual NFR targets/requirements for 14.1 through 14.7 (or confirm which existing document supersedes this section). | G12: No
A13: 9 | B13: Incident Closure | C13: Section 5.10.1(h)/(i) separation-of-duties rule (DM cannot endorse closure of an incident they created/submitted/resubmitted themselves, even while elevated) is not implemented in code at all. | D13: 5.10.1 | E13: High-priority compliance control gap, not a spec ambiguity - flagging for BA awareness/prioritisation | F13: Confirm priority/timeline for building the separation-of-duties enforcement, and whether 'actor identity' should be tracked via a new submittedBy/resubmittedBy field. | G13: No
A14: 10 | B14: e-Diary | C14: Code makes e-Diary entries fully immutable (no edit, no delete for any role, citing an internal comment referencing 'FRD Section 8.2'), which is the OPPOSITE of FRD 9.1(c) which requires entries to be editable with tracked amendments and deletion restricted to System Administrator only. | D14: 9.1(c) | E14: Direct contradiction between current code behaviour and FRD text - needs explicit resolution | F14: Confirm the intended e-Diary mutability model: should entries be editable with amendment tracking (per FRD 9.1c), or permanently immutable (per current code)? | G14: No
A15: 11 | B15: Broadcast | C15: No Controller-facing compose/confirm/dispatch UI exists anywhere - Closure Broadcasts auto-queue to 'Pending' status on incident close but can never actually be dispatched through the app. /broadcasts page is a literal 'Coming soon' stub. | D15: 5.11.1 / 10.1 / 10.9 | E15: Core Broadcast dispatch workflow appears entirely unbuilt despite supporting config/data-model pieces existing | F15: Confirm Broadcast dispatch (compose/review/send) is planned for a specific upcoming phase, and get prioritisation relative to other gaps. | G15: No
A16: 12 | B16: Crisis Management | C16: Crisis Recall (entire Section 11) is essentially unbuilt - an orphaned SMS mock endpoint exists but nothing calls it; no Recall Groups, no recall routing/config, no DM review-and-confirm workflow. | D16: 11.1-11.5 | E16: Entire module absent - confirm scope/priority for this phase | F16: Is Crisis Recall in scope for the current build phase? If so, what SMS gateway/provider should the mock be replaced with? | G16: No
A17: 13 | B17: Reporting & Data Export | C17: Entire Section 12 (Operational Statistics, Incident/Case export, Analytics export) is unbuilt - /statistics is a 'Coming soon' stub and there is no PDF/CSV export feature anywhere in the app. | D17: 12.1-12.4 | E17: Entire module absent - confirm scope/priority for this phase | F17: Confirm priority/timeline for Reporting & Data Export, and whether PDF export or CSV-only is the minimum viable requirement. | G17: No
A18: 14 | B18: Authentication | C18: No real authentication exists - RoleContext is a client-side, localStorage-persisted role switcher usable by anyone with the URL. WOG SSO, 2FA, and access-denial for unauthorised accounts are entirely unbuilt. | D18: 2.3.1 | E18: Foundational security gap - confirm this is accepted as a prototype-phase limitation | F18: Confirm whether WOG SSO integration is planned before go-live, and what the target timeline/owner is (likely an infra/platform-team dependency, not pure CMS-team scope). | G18: No
A19: 15 | B19: Dashboard / Map | C19: '2D Island Map' runs on Leaflet + OpenStreetMap/CartoDB tiles, not OneMap as specified; only a cosmetic UI label says 'OneMap API Layout'. No geocoding, no Faults layer, no NOP boundary layer, no pin clustering. | D19: 2.4.4 | E19: Named integration (OneMap) does not exist in code at all - a material gap from the named requirement | F19: Confirm whether OneMap API integration (incl. geocoding) is still required, or whether the current OSM/Leaflet map is an accepted substitute. | G19: No
A20: 16 | B20: Roles & Permissions | C20: The Admin > Roles permission matrix (admin/roles/page.tsx) is a fully built, nice-looking UI but is not read by any other part of the app - actual permission gating elsewhere is hardcoded per-page. Editing the matrix has no functional effect. | D20: 3.1 / 3.3 | E20: Risk that stakeholders believe editing this screen changes real permissions when it does not | F20: Confirm whether wiring the Roles matrix into live permission checks is planned, or whether hardcoded per-page gating is the accepted long-term approach. | G20: No
A21: 17 | B21: Duty Manager Elevation | C21: Section 3.2 elevation model (admin-granted, shift-boxed, grace-period auto-expiring, applies to Controller too per v0.5) is not implemented - only a self-service, non-persisted Duty-Officer-only toggle exists in the sidebar. | D21: 3.2 | E21: Large v0.4->v0.5 behavioural change with zero implementation and no data model | F21: Confirm priority/timeline for building the full Duty Manager Elevation workflow (admin grant, shift dates, grace period, Controller eligibility). | G21: No
A22: 18 | B22: Missing Roles | C22: Zone/Contract Manager (Non-IFM), NOP Applicant (SDC Term-Contractor), and NOP Approver (SDC Term-Contractor) roles from FRD 3.1 do not exist anywhere in the switchable role model. | D22: 3.1 | E22: Roles referenced in FRD's own role table have no corresponding code representation | F22: Confirm whether these 3 roles are still required for the current build phase, and their exact permission scope. | G22: No
A23: 19 | B23: Data Persistence | C23: Several admin config surfaces (Users, Roles, Distribution Groups, Broadcast Config/Matrix/Templates, Taxonomy) persist to browser localStorage rather than a shared server database - changes don't propagate across users/sessions. | D23: 13.1-13.4 (cross-cutting) | E23: Material architecture gap for any real multi-admin/production deployment | F23: Confirm whether backend/shared-DB persistence for admin configuration is planned before go-live, and get it prioritised/sequenced with the tech lead. | G23: No
